Workbook

Sheet Items
A1: Ítem | B1: Unidad | C1: Cantidad | D1: Precio unitario ($) | E1: Total ($)
E2: =IF(OR(A2="",C2="",D2=""),"",C2*D2)
E3: =IF(OR(A3="",C3="",D3=""),"",C3*D3)
E4: =IF(OR(A4="",C4="",D4=""),"",C4*D4)
E5: =IF(OR(A5="",C5="",D5=""),"",C5*D5)
E6: =IF(OR(A6="",C6="",D6=""),"",C6*D6)
E7: =IF(OR(A7="",C7="",D7=""),"",C7*D7)
E8: =IF(OR(A8="",C8="",D8=""),"",C8*D8)
E9: =IF(OR(A9="",C9="",D9=""),"",C9*D9)
E10: =IF(OR(A10="",C10="",D10=""),"",C10*D10)
E11: =IF(OR(A11="",C11="",D11=""),"",C11*D11)
E12: =IF(OR(A12="",C12="",D12=""),"",C12*D12)
E13: =IF(OR(A13="",C13="",D13=""),"",C13*D13)
... E51: =IF(OR(A51="",C51="",D51=""),"",C51*D51)
A53: * La columna Total se calcula automáticamente. No la edites.
A54: * Completá solo las columnas blancas y azules. Máx. 50 ítems.

Sheet _Factores_Ref
A1: Nro | B1: Nombre
A2: 1 | B2: Aceros
A3: 2 | B3: Aireadores
A4: 3 | B4: Aisl. mors. herrajes
A5: 4 | B5: Alambres, aluminio y cerámica
A6: 5 | B6: Albañilería
A7: 6 | B7: Áridos
A8: 7 | B8: Áridos Triturados
A9: 8 | B9: Asfaltos
A10: 9 | B10: Cable
A11: 10 | B11: Caños de PRFV
A12: 11 | B12: Caños de PVC
A13: 12 | B13: Carpintería
... A47: 46 | B47: Empalmes y terminales

Sheet Factores
A1: Ítem (de la hoja Items) | B1: Nro. factor | C1: Nombre del factor | D1: Peso (%)
A2: =IF(Items!A2="","",Items!A2) | C2: =IF(OR(B2="",A2=""),"",IFERROR(VLOOKUP(B2,_Factores_Ref!$A:$B,2,FALSE),"Factor no encontrado"))
A3: =IF(Items!A2="","",Items!A2) | C3: =IF(OR(B3="",A3=""),"",IFERROR(VLOOKUP(B3,_Factores_Ref!$A:$B,2,FALSE),"Factor no encontrado"))
A4: =IF(Items!A2="","",Items!A2) | C4: =IF(OR(B4="",A4=""),"",IFERROR(VLOOKUP(B4,_Factores_Ref!$A:$B,2,FALSE),"Factor no encontrado"))
A5: =IF(Items!A2="","",Items!A2) | C5: =IF(OR(B5="",A5=""),"",IFERROR(VLOOKUP(B5,_Factores_Ref!$A:$B,2,FALSE),"Factor no encontrado"))
A6: =IF(Items!A2="","",Items!A2) | C6: =IF(OR(B6="",A6=""),"",IFERROR(VLOOKUP(B6,_Factores_Ref!$A:$B,2,FALSE),"Factor no encontrado"))
A7: =IF(Items!A2="","",Items!A2) | C7: =IF(OR(B7="",A7=""),"",IFERROR(VLOOKUP(B7,_Factores_Ref!$A:$B,2,FALSE),"Factor no encontrado"))
A8: =IF(Items!A2="","",Items!A2) | C8: =IF(OR(B8="",A8=""),"",IFERROR(VLOOKUP(B8,_Factores_Ref!$A:$B,2,FALSE),"Factor no encontrado"))
A9: =IF(Items!A2="","",Items!A2) | C9: =IF(OR(B9="",A9=""),"",IFERROR(VLOOKUP(B9,_Factores_Ref!$A:$B,2,FALSE),"Factor no encontrado"))
A10: =IF(Items!A2="","",Items!A2) | C10: =IF(OR(B10="",A10=""),"",IFERROR(VLOOKUP(B10,_Factores_Ref!$A:$B,2,FALSE),"Factor no encontrado"))
A11: =IF(Items!A2="","",Items!A2) | C11: =IF(OR(B11="",A11=""),"",IFERROR(VLOOKUP(B11,_Factores_Ref!$A:$B,2,FALSE),"Factor no encontrado"))
A12: =IF(Items!A3="","",Items!A3) | C12: =IF(OR(B12="",A12=""),"",IFERROR(VLOOKUP(B12,_Factores_Ref!$A:$B,2,FALSE),"Factor no encontrado"))
A13: =IF(Items!A3="","",Items!A3) | C13: =IF(OR(B13="",A13=""),"",IFERROR(VLOOKUP(B13,_Factores_Ref!$A:$B,2,FALSE),"Factor no encontrado"))
A14: =IF(Items!A3="","",Items!A3) | C14: =IF(OR(B14="",A14=""),"",IFERROR(VLOOKUP(B14,_Factores_Ref!$A:$B,2,FALSE),"Factor no encontrado"))
A15: =IF(Items!A3="","",Items!A3) | C15: =IF(OR(B15="",A15=""),"",IFERROR(VLOOKUP(B15,_Factores_Ref!$A:$B,2,FALSE),"Factor no encontrado"))
A16: =IF(Items!A3="","",Items!A3) | C16: =IF(OR(B16="",A16=""),"",IFERROR(VLOOKUP(B16,_Factores_Ref!$A:$B,2,FALSE),"Factor no encontrado"))
A17: =IF(Items!A3="","",Items!A3) | C17: =IF(OR(B17="",A17=""),"",IFERROR(VLOOKUP(B17,_Factores_Ref!$A:$B,2,FALSE),"Factor no encontrado"))
A18: =IF(Items!A3="","",Items!A3) | C18: =IF(OR(B18="",A18=""),"",IFERROR(VLOOKUP(B18,_Factores_Ref!$A:$B,2,FALSE),"Factor no encontrado"))
A19: =IF(Items!A3="","",Items!A3) | C19: =IF(OR(B19="",A19=""),"",IFERROR(VLOOKUP(B19,_Factores_Ref!$A:$B,2,FALSE),"Factor no encontrado"))
A20: =IF(Items!A3="","",Items!A3) | C20: =IF(OR(B20="",A20=""),"",IFERROR(VLOOKUP(B20,_Factores_Ref!$A:$B,2,FALSE),"Factor no encontrado"))
A21: =IF(Items!A3="","",Items!A3) | C21: =IF(OR(B21="",A21=""),"",IFERROR(VLOOKUP(B21,_Factores_Ref!$A:$B,2,FALSE),"Factor no encontrado"))
A22: =IF(Items!A4="","",Items!A4) | C22: =IF(OR(B22="",A22=""),"",IFERROR(VLOOKUP(B22,_Factores_Ref!$A:$B,2,FALSE),"Factor no encontrado"))
A23: =IF(Items!A4="","",Items!A4) | C23: =IF(OR(B23="",A23=""),"",IFERROR(VLOOKUP(B23,_Factores_Ref!$A:$B,2,FALSE),"Factor no encontrado"))
A24: =IF(Items!A4="","",Items!A4) | C24: =IF(OR(B24="",A24=""),"",IFERROR(VLOOKUP(B24,_Factores_Ref!$A:$B,2,FALSE),"Factor no encontrado"))
A25: =IF(Items!A4="","",Items!A4) | C25: =IF(OR(B25="",A25=""),"",IFERROR(VLOOKUP(B25,_Factores_Ref!$A:$B,2,FALSE),"Factor no encontrado"))
A26: =IF(Items!A4="","",Items!A4) | C26: =IF(OR(B26="",A26=""),"",IFERROR(VLOOKUP(B26,_Factores_Ref!$A:$B,2,FALSE),"Factor no encontrado"))
A27: =IF(Items!A4="","",Items!A4) | C27: =IF(OR(B27="",A27=""),"",IFERROR(VLOOKUP(B27,_Factores_Ref!$A:$B,2,FALSE),"Factor no encontrado"))
A28: =IF(Items!A4="","",Items!A4) | C28: =IF(OR(B28="",A28=""),"",IFERROR(VLOOKUP(B28,_Factores_Ref!$A:$B,2,FALSE),"Factor no encontrado"))
A29: =IF(Items!A4="","",Items!A4) | C29: =IF(OR(B29="",A29=""),"",IFERROR(VLOOKUP(B29,_Factores_Ref!$A:$B,2,FALSE),"Factor no encontrado"))
A30: =IF(Items!A4="","",Items!A4) | C30: =IF(OR(B30="",A30=""),"",IFERROR(VLOOKUP(B30,_Factores_Ref!$A:$B,2,FALSE),"Factor no encontrado"))
A31: =IF(Items!A4="","",Items!A4) | C31: =IF(OR(B31="",A31=""),"",IFERROR(VLOOKUP(B31,_Factores_Ref!$A:$B,2,FALSE),"Factor no encontrado"))
A32: =IF(Items!A5="","",Items!A5) | C32: =IF(OR(B32="",A32=""),"",IFERROR(VLOOKUP(B32,_Factores_Ref!$A:$B,2,FALSE),"Factor no encontrado"))
A33: =IF(Items!A5="","",Items!A5) | C33: =IF(OR(B33="",A33=""),"",IFERROR(VLOOKUP(B33,_Factores_Ref!$A:$B,2,FALSE),"Factor no encontrado"))
A34: =IF(Items!A5="","",Items!A5) | C34: =IF(OR(B34="",A34=""),"",IFERROR(VLOOKUP(B34,_Factores_Ref!$A:$B,2,FALSE),"Factor no encontrado"))
A35: =IF(Items!A5="","",Items!A5) | C35: =IF(OR(B35="",A35=""),"",IFERROR(VLOOKUP(B35,_Factores_Ref!$A:$B,2,FALSE),"Factor no encontrado"))
A36: =IF(Items!A5="","",Items!A5) | C36: =IF(OR(B36="",A36=""),"",IFERROR(VLOOKUP(B36,_Factores_Ref!$A:$B,2,FALSE),"Factor no encontrado"))
A37: =IF(Items!A5="","",Items!A5) | C37: =IF(OR(B37="",A37=""),"",IFERROR(VLOOKUP(B37,_Factores_Ref!$A:$B,2,FALSE),"Factor no encontrado"))
A38: =IF(Items!A5="","",Items!A5) | C38: =IF(OR(B38="",A38=""),"",IFERROR(VLOOKUP(B38,_Factores_Ref!$A:$B,2,FALSE),"Factor no encontrado"))
A39: =IF(Items!A5="","",Items!A5) | C39: =IF(OR(B39="",A39=""),"",IFERROR(VLOOKUP(B39,_Factores_Ref!$A:$B,2,FALSE),"Factor no encontrado"))
A40: =IF(Items!A5="","",Items!A5) | C40: =IF(OR(B40="",A40=""),"",IFERROR(VLOOKUP(B40,_Factores_Ref!$A:$B,2,FALSE),"Factor no encontrado"))
...
